2024-05-13 17:27:22,292 FILE: creds.py IN: create_new_token MESSAGE: Ошибка получения iam_token: HTTPConnectionPool(host='169.254.169.254', port=80): Max retries exceeded with url: /computeMetadata/v1/instance/service-accounts/default/token (Caused by ConnectTimeoutError(<urllib3.connection.HTTPConnection object at 0x000002680AD5D9A0>, 'Connection to 169.254.169.254 timed out. (connect timeout=None)'))
